Workbook

Sheet Budget
A2: TIMBERLINE BUILD CO.
A4: PROJECT BUDGET — INTERNAL WORKING DOCUMENT
A5: Client Name: | B5: Hank Fos | E5: Date: | F5: 46147
A6: Project Address: | B6: 7 St Elizabeth, Laguna Niguel, CA 92677 | E6: Default Markup: | F6: 0.4
A7: Project Type: | B7: Master Bathroom Remodel | E7: Project #:
A8: Estimator: | B8: Justin | E8: License #:
A10: Category | B10: Item / Description | C10: Material Cost | D10: Labor Cost | E10: M&L Total | F10: Markup % | G10: Client Price | H10: Mat. Allowance? | I10: Notes
C11: what YOU pay | D11: what YOU pay | E11: =C+D | F11: default 40% | G11: =E×(1+F) | H11: ✔ = excl. Gary
A12: ▸ DEMO
B13: Demo & Haul Away | E13: =IFERROR(C13+D13,0) | F13: =$F$6 | G13: =IFERROR(E13*(1+F13),0) | H13: —
B14: Dumpster Rental | E14: =IFERROR(C14+D14,0) | F14: =$F$6 | G14: =IFERROR(E14*(1+F14),0) | H14: —
A15: Demo Subtotal | C15: =SUM(C13:C14) | D15: =SUM(D13:D14) | E15: =SUM(E13:E14) | G15: =SUM(G13:G14) | H15: =SUMIF(H13:H14,"✔",G13:G14)
A17: ▸ KITCHEN
B18: Cabinet Install | E18: =IFERROR(C18+D18,0) | F18: =$F$6 | G18: =IFERROR(E18*(1+F18),0) | H18: —
B19: Cabinets (Material Allowance) | E19: =IFERROR(C19+D19,0) | F19: =$F$6 | G19: =IFERROR(E19*(1+F19),0) | H19: ✔
B20: Countertop Install | E20: =IFERROR(C20+D20,0) | F20: =$F$6 | G20: =IFERROR(E20*(1+F20),0) | H20: —
B21: Countertop Material | E21: =IFERROR(C21+D21,0) | F21: =$F$6 | G21: =IFERROR(E21*(1+F21),0) | H21: ✔
B22: Backsplash — Labor | E22: =IFERROR(C22+D22,0) | F22: =$F$6 | G22: =IFERROR(E22*(1+F22),0) | H22: —
B23: Backsplash — Material | E23: =IFERROR(C23+D23,0) | F23: =$F$6 | G23: =IFERROR(E23*(1+F23),0) | H23: ✔
B24: Plumbing (rough + finish) | E24: =IFERROR(C24+D24,0) | F24: =$F$6 | G24: =IFERROR(E24*(1+F24),0) | H24: —
B25: Electrical | E25: =IFERROR(C25+D25,0) | F25: =$F$6 | G25: =IFERROR(E25*(1+F25),0) | H25: —
B26: Fixtures Allowance | E26: =IFERROR(C26+D26,0) | F26: =$F$6 | G26: =IFERROR(E26*(1+F26),0) | H26: ✔
B27: Appliance Hookup | E27: =IFERROR(C27+D27,0) | F27: =$F$6 | G27: =IFERROR(E27*(1+F27),0) | H27: —
B28: Drywall Repair | E28: =IFERROR(C28+D28,0) | F28: =$F$6 | G28: =IFERROR(E28*(1+F28),0) | H28: —
B29: Paint | E29: =IFERROR(C29+D29,0) | F29: =$F$6 | G29: =IFERROR(E29*(1+F29),0) | H29: —
A30: Kitchen Subtotal | C30: =SUM(C18:C29) | D30: =SUM(D18:D29) | E30: =SUM(E18:E29) | G30: =SUM(G18:G29) | H30: =SUMIF(H18:H29,"✔",G18:G29)
A32: ▸ BATHROOM
B33: Demo & Haul Away | C33: 0 | D33: 1000 | E33: =IFERROR(C33+D33,0) | F33: =$F$6 | G33: =IFERROR(E33*(1+F33),0) | H33: —
B34: Waterproofing / Hot Mop | C34: 0 | D34: 550 | E34: =IFERROR(C34+D34,0) | F34: =$F$6 | G34: =IFERROR(E34*(1+F34),0) | H34: —
B35: Tile Labor — Shower & Toilet Room Walls (96" high, niche) | C35: 0 | D35: 3400 | E35: =IFERROR(C35+D35,0) | F35: =$F$6 | G35: =IFERROR(E35*(1+F35),0) | H35: —
B36: Shower Tile (Allowance) | C36: 1600 | D36: 0 | E36: =IFERROR(C36+D36,0) | F36: 0 | G36: =IFERROR(E36*(1+F36),0) | H36: ✔
B37: Plumbing — Shower, 2 Sinks, Bidet Rough-in | C37: 0 | D37: 1000 | E37: =IFERROR(C37+D37,0) | F37: =$F$6 | G37: =IFERROR(E37*(1+F37),0) | H37: —
B38: Floor Tile (Allowance) | C38: 500 | D38: 0 | E38: =IFERROR(C38+D38,0) | F38: 0 | G38: =IFERROR(E38*(1+F38),0) | H38: ✔
B39: Set Vanity + Plumb 2 Sinks (client-supplied vanity/faucets) | C39: 0 | D39: 600 | E39: =IFERROR(C39+D39,0) | F39: =$F$6 | G39: =IFERROR(E39*(1+F39),0) | H39: —
B40: Double Sink Vanity (Allowance) | C40: 1000 | D40: 0 | E40: =IFERROR(C40+D40,0) | F40: 0 | G40: =IFERROR(E40*(1+F40),0) | H40: ✔
B41: Bidet Toilet (Allowance — Pass-through) | C41: 1000 | D41: 0 | E41: =IFERROR(C41+D41,0) | F41: 0 | G41: =IFERROR(E41*(1+F41),0) | H41: ✔
B42: Pocket Door — Frame + Install | C42: 0 | D42: 1200 | E42: =IFERROR(C42+D42,0) | F42: =$F$6 | G42: =IFERROR(E42*(1+F42),0) | H42: —
B43: Electrical — Bidet Circuit, Vent Fan, Mirror Lights x2, Relocate Switch/Outlet | C43: 0 | D43: 900 | E43: =IFERROR(C43+D43,0) | F43: =$F$6 | G43: =IFERROR(E43*(1+F43),0) | H43: —
B44: Drywall / Backer / Soffit Removal + Patch | C44: 0 | D44: 800 | E44: =IFERROR(C44+D44,0) | F44: =$F$6 | G44: =IFERROR(E44*(1+F44),0) | H44: —
B45: Hang Mirrors (owner-supplied), Towel Bar, TP Holder | C45: 0 | D45: 150 | E45: =IFERROR(C45+D45,0) | F45: =$F$6 | G45: =IFERROR(E45*(1+F45),0) | H45: —
...

Sheet Materials
A2: TIMBERLINE BUILD CO.
A4: MATERIALS TRACKER
A5: Item / Description | B5: Supplier | C5: Unit Cost | D5: Qty | E5: Total | F5: Status | G5: Notes
E6: =IFERROR(C6*D6,"")
E7: =IFERROR(C7*D7,"")
E8: =IFERROR(C8*D8,"")
E9: =IFERROR(C9*D9,"")
E10: =IFERROR(C10*D10,"")
E11: =IFERROR(C11*D11,"")
E12: =IFERROR(C12*D12,"")
E13: =IFERROR(C13*D13,"")
E14: =IFERROR(C14*D14,"")
E15: =IFERROR(C15*D15,"")
E16: =IFERROR(C16*D16,"")
E17: =IFERROR(C17*D17,"")
... E50: =IFERROR(C50*D50,"")
A51: Total Materials Cost | E51: =SUM(E6:E50)

Sheet Client Summary
A2: TIMBERLINE BUILD CO.
A4: INVESTMENT ESTIMATE
A6: Client: | B6: =Budget!B5
A7: Property: | B7: =Budget!B6
A8: Project Type: | B8: =Budget!B7
A9: Estimate Date: | B9: =Budget!F5
A11: SCOPE OF WORK — COST BREAKDOWN
A12: Demo | B12: =Budget!G15
A13: Kitchen | B13: =Budget!G30
A14: Bathroom | B14: =Budget!G48
A15: Flooring | B15: =Budget!G55
A16: Paint & Drywall | B16: =Budget!G62
A17: Electrical | B17: =Budget!G69
A18: Plumbing | B18: =Budget!G76
A19: Misc / Extra | B19: =Budget!G84
A21: TOTAL PROJECT INVESTMENT | B21: =Budget!G90
A23: timberlinebuild.co · Estimate valid 30 days · CA Contractor License #pending

Sheet Profit Breakdown
A2: TIMBERLINE BUILD CO.
A4: JOB PROFIT BREAKDOWN
A6: Client Name | B6: =Budget!B5
A7: Project Address | B7: =Budget!B6
A8: Project Type | B8: =Budget!B7
A9: Date | B9: =Budget!F5
A11: CLIENT TOTAL | B11: =Budget!G90
A12: Your Total Cost | B12: =Budget!G88
A13: Material Allowances | B13: =Budget!G89
A14: Gross Profit | B14: =Budget!G92
A15: Gary's Cut (10%) | B15: =Budget!G91
A16: Change Orders | B16: =Budget!G103
A17: MY TAKE HOME | B17: =Budget!G93+Budget!G103
A19: Profit Margin % | B19: =IFERROR(B17/B11,0)
A20: Effective Markup % | B20: =IFERROR((B11-B12)/B12,0)
A22: PAYMENT TRACKING
A23: Payment # | B23: Amount | C23: Date
A24: Payment 1
A25: Payment 2
A26: Payment 3
A27: Payment 4
A28: Payment 5
A29: Payment 6
A30: Total Paid | B30: =SUM(B24:B29) | C30: =B11-B30
